Workbook

Sheet Sheet1
B1: Whatsapp | C1: Donatur | D1: CRM | E1: start_date | F1: No
A2: 0 | B2: 6281348526369 | C2: Mustakim | D2: WA_7778 | E2: 45931
A3: 1 | B3: 6285255859869 | C3: Nurhikmah | D3: WA_7778 | E3: 45931
A4: 2 | B4: 6285273861086 | C4: Khasndra | D4: WA_7778 | E4: 45931
A5: 3 | B5: 6285273908199 | C5: Dewi Sartika | D5: WA_7778 | E5: 45931
A6: 4 | B6: 6281330740765 | C6: Rusdi | D6: WA_7778 | E6: 45931
A7: 5 | B7: 6285274159404 | C7: Ernawati Nusi | D7: WA_7778 | E7: 45931
A8: 6 | B8: 6285276294437 | C8: Hamba Allah | D8: WA_7778 | E8: 45931
A9: 7 | B9: 6281328742768 | C9: hamba alloh | D9: WA_7778 | E9: 45931
A10: 8 | B10: 6285277660331 | C10: Asrihasan | D10: WA_7778 | E10: 45931
A11: 9 | B11: 6285277893569 | C11: Hermiana br sihombing | D11: WA_7778 | E11: 45931
A12: 10 | B12: 6285275375159 | C12: Nurul Hidayah | D12: WA_7778 | E12: 45931
A13: 11 | B13: 6285259091917 | C13: Lionel | D13: WA_7778 | E13: 45931
... A88: 86 | B88: 6281293261968 | C88: Hamba alloh | D88: WA_7778 | E88: 45931
A89: 87 | B89: 6285342706561 | C89: BundaHafizHadiq | D89: Eliminated
A90: 88 | B90: 6281310701768 | C90: iren rachman | D90: WA_7778 | E90: 45931
A91: 89 | B91: 6281310535582 | C91: Saodah Yoni | D91: WA_7778 | E91: 45931
A92: 90 | B92: 6285343684355 | C92: Kamaria Badaring | D92: WA_7778 | E92: 45931
A93: 91 | B93: 6281365618979 | C93: Firdaus bin samiakfirda salon | D93: WA_7778 | E93: 45931
A94: 92 | B94: 6285343757834 | C94: Sartika Wati | D94: WA_7778 | E94: 45931
A95: 93 | B95: 6285344113747 | C95: Theresia oktavini | D95: WA_7778 | E95: 45931
A96: 94 | B96: 6281310249945 | C96: Siti Khairiyah | D96: WA_7778 | E96: 45931
A97: 95 | B97: 6285240387411 | C97: Moh Taufiq kumali | D97: WA_7778 | E97: 45931
A98: 96 | B98: 6285239620497 | C98: Sumarni | D98: WA_7778 | E98: 45931
A99: 97 | B99: 6285347459963 | C99: Diana | D99: WA_7778 | E99: 45931
A100: 98 | B100: 6285349452081 | C100: Anton | D100: WA_7778 | E100: 45931
A101: 99 | B101: 6281366146555 | C101: Nopriyandi | D101: WA_7778 | E101: 45931
... A182: 180 | B182: 6282183836604 | C182: Januar iskandar muda | D182: WA_7778 | E182: 45931
A183: 181 | B183: 628126478757 | C183: Noviandri | D183: Eliminated
A184: 182 | B184: 6287875265156 | C184: Nida Nurma Utami | D184: WA_7778 | E184: 45931
A185: 183 | B185: 6282143997273 | C185: Prapti M | D185: WA_7778 | E185: 45931
A186: 184 | B186: 6282285668796 | C186: Nandang sahyana | D186: WA_7778 | E186: 45931
A187: 185 | B187: 628126728557 | C187: Ratnawilis | D187: WA_7778 | E187: 45931
A188: 186 | B188: 6282143394948 | C188: fatma rindu | D188: WA_7778 | E188: 45931
A189: 187 | B189: 6282252317779 | C189: Ida Royanti | D189: WA_7778 | E189: 45931
A190: 188 | B190: 6282250220204 | C190: Syamsuddin | D190: WA_7778 | E190: 45931
A191: 189 | B191: 628125100716 | C191: Pribakti Budinurdjaja | D191: WA_7778 | E191: 45931
A192: 190 | B192: 6282137364579 | C192: Dapur Pakde Falah | D192: WA_7778 | E192: 45931
A193: 191 | B193: 6287838846543 | C193: Munir | D193: WA_7778 | E193: 45931
A194: 192 | B194: 62818591940 | C194: Ike | D194: WA_7778 | E194: 45931
...

Sheet Sheet2
A1: nomor | B1: wa
A2: 6281280258518 | B2: =VLOOKUP(A2,Sheet1!$B$2:$D$70347,3,0) -> WA_2057_1 | E2: Row Labels | F2: Count of nomor
A3: 6287786602539 | B3: =VLOOKUP(A3,Sheet1!$B$2:$D$70347,3,0) -> WA_2057_1 | E3: Refill_WA_2058_2 | F3: 23
A4: 6285240407337 | B4: =VLOOKUP(A4,Sheet1!$B$2:$D$70347,3,0) -> WA_2057_1 | E4: WA_2056_1 | F4: 1
A5: 628113312332 | B5: =VLOOKUP(A5,Sheet1!$B$2:$D$70347,3,0) -> WA_2057_1 | E5: WA_2057_1 | F5: 484
A6: 6281365319444 | B6: =VLOOKUP(A6,Sheet1!$B$2:$D$70347,3,0) -> WA_2057_1 | E6: WA_2060_2 | F6: 487
A7: 6281244075707 | B7: =VLOOKUP(A7,Sheet1!$B$2:$D$70347,3,0) -> WA_2057_1 | E7: #N/A | F7: 7
A8: 6287878139524 | B8: =VLOOKUP(A8,Sheet1!$B$2:$D$70347,3,0) -> WA_2057_1 | E8: (blank)
A9: 6288213142414 | B9: =VLOOKUP(A9,Sheet1!$B$2:$D$70347,3,0) -> WA_2057_1 | E9: Grand Total | F9: 1002
A10: 6285233531300 | B10: =VLOOKUP(A10,Sheet1!$B$2:$D$70347,3,0) -> WA_2057_1
A11: 6281266705556 | B11: =VLOOKUP(A11,Sheet1!$B$2:$D$70347,3,0) -> WA_2057_1
A12: 6285277685171 | B12: =VLOOKUP(A12,Sheet1!$B$2:$D$70347,3,0) -> WA_2057_1
A13: 6285364753541 | B13: =VLOOKUP(A13,Sheet1!$B$2:$D$70347,3,0) -> WA_2057_1
A14: 628126628810 | B14: =VLOOKUP(A14,Sheet1!$B$2:$D$70347,3,0) -> WA_2057_1
A15: 6281296288677 | B15: =VLOOKUP(A15,Sheet1!$B$2:$D$70347,3,0) -> WA_2057_1
A16: 628111667204 | B16: =VLOOKUP(A16,Sheet1!$B$2:$D$70347,3,0) -> WA_2057_1
A17: 6287877830094 | B17: =VLOOKUP(A17,Sheet1!$B$2:$D$70347,3,0) -> WA_2057_1
A18: 6282224269730 | B18: =VLOOKUP(A18,Sheet1!$B$2:$D$70347,3,0) -> WA_2057_1
A19: 6289662971198 | B19: =VLOOKUP(A19,Sheet1!$B$2:$D$70347,3,0) -> WA_2057_1
A20: 6281380539989 | B20: =VLOOKUP(A20,Sheet1!$B$2:$D$70347,3,0) -> WA_2057_1
A21: 6281372826128 | B21: =VLOOKUP(A21,Sheet1!$B$2:$D$70347,3,0) -> WA_2057_1
... A1003: 6282110734086 | B1003: =VLOOKUP(A1003,Sheet1!$B$2:$D$70347,3,0) -> WA_2057_1
