Workbook

Sheet Donatur Baru 
A1: No | B1: Tanggal | C1: No CS | D1: Donatur | E1: Whatsapp | F1: Donasi Sebelumnya | G1: Periode Prospek | H1: Program | I1: Entri Donatur | J1: Tanggal 1 | K1: Action 1 | L1: Respon 1 | M1: Donasi 1 | N1: Tanggal 2 | O1: Action 2 | P1: Respon 2 | Q1: Donasi 2 | R1: Tanggal 3 | S1: Action 3 | T1: Respon 3 | U1: Donasi 3 | V1: Catatan | W1: Next Action
A2: 257 | D2: Hamba allah | E2: 6282395704407 | G2: Bukan Gajian | H2: PALESTINA | I2: March | J2: =_xlfn.IFNA(LEFT(VLOOKUP($E2,data_rekap_respon_1!$A:$E,3,0),10),"") | L2: =_xlfn.IFNA( IF(VLOOKUP($E2, data_rekap_respon_1!$A:$E, 4, 0)="read", "Read", IF(VLOOKUP($E2, data_rekap_respon_1!$A:$E, 4, 0)="failed", IF(VLOOKUP($E2, data_rekap_respon_1!$A:$E, 5, 0)="Message Undeliverable.", "Invalid", "Failed"), "Received") ), "" )
A3: 613 | D3: Hamba Allah | E3: 6281295886020 | G3: Bukan Gajian | H3: PALESTINA | I3: April | J3: =_xlfn.IFNA(LEFT(VLOOKUP($E3,data_rekap_respon_1!$A:$E,3,0),10),"") | L3: =_xlfn.IFNA( IF(VLOOKUP($E3, data_rekap_respon_1!$A:$E, 4, 0)="read", "Read", IF(VLOOKUP($E3, data_rekap_respon_1!$A:$E, 4, 0)="failed", IF(VLOOKUP($E3, data_rekap_respon_1!$A:$E, 5, 0)="Message Undeliverable.", "Invalid", "Failed"), "Received") ), "" )
A4: 759 | D4: Hamba Allah | E4: 6281253701238 | G4: Bukan Gajian | H4: PALESTINA | I4: April | J4: =_xlfn.IFNA(LEFT(VLOOKUP($E4,data_rekap_respon_1!$A:$E,3,0),10),"") | L4: =_xlfn.IFNA( IF(VLOOKUP($E4, data_rekap_respon_1!$A:$E, 4, 0)="read", "Read", IF(VLOOKUP($E4, data_rekap_respon_1!$A:$E, 4, 0)="failed", IF(VLOOKUP($E4, data_rekap_respon_1!$A:$E, 5, 0)="Message Undeliverable.", "Invalid", "Failed"), "Received") ), "" )
A5: 882 | D5: Hamba Allah | E5: 6281213861160 | G5: Bukan Gajian | H5: PALESTINA | I5: April | J5: =_xlfn.IFNA(LEFT(VLOOKUP($E5,data_rekap_respon_1!$A:$E,3,0),10),"") | L5: =_xlfn.IFNA( IF(VLOOKUP($E5, data_rekap_respon_1!$A:$E, 4, 0)="read", "Read", IF(VLOOKUP($E5, data_rekap_respon_1!$A:$E, 4, 0)="failed", IF(VLOOKUP($E5, data_rekap_respon_1!$A:$E, 5, 0)="Message Undeliverable.", "Invalid", "Failed"), "Received") ), "" )
A6: 955 | D6: Hamba allah | E6: 6281241917141 | G6: Bukan Gajian | H6: PALESTINA | I6: April | J6: =_xlfn.IFNA(LEFT(VLOOKUP($E6,data_rekap_respon_1!$A:$E,3,0),10),"") | L6: =_xlfn.IFNA( IF(VLOOKUP($E6, data_rekap_respon_1!$A:$E, 4, 0)="read", "Read", IF(VLOOKUP($E6, data_rekap_respon_1!$A:$E, 4, 0)="failed", IF(VLOOKUP($E6, data_rekap_respon_1!$A:$E, 5, 0)="Message Undeliverable.", "Invalid", "Failed"), "Received") ), "" )
A7: 1013 | D7: Hamba Allah | E7: 6281279892370 | G7: Masa Gajian | H7: PALESTINA | I7: April | J7: =_xlfn.IFNA(LEFT(VLOOKUP($E7,data_rekap_respon_1!$A:$E,3,0),10),"") | L7: =_xlfn.IFNA( IF(VLOOKUP($E7, data_rekap_respon_1!$A:$E, 4, 0)="read", "Read", IF(VLOOKUP($E7, data_rekap_respon_1!$A:$E, 4, 0)="failed", IF(VLOOKUP($E7, data_rekap_respon_1!$A:$E, 5, 0)="Message Undeliverable.", "Invalid", "Failed"), "Received") ), "" )
A8: 1195 | D8: Hamba Allah | E8: 6283878939922 | G8: Bukan Gajian | H8: PALESTINA | I8: May | J8: =_xlfn.IFNA(LEFT(VLOOKUP($E8,data_rekap_respon_1!$A:$E,3,0),10),"") | L8: =_xlfn.IFNA( IF(VLOOKUP($E8, data_rekap_respon_1!$A:$E, 4, 0)="read", "Read", IF(VLOOKUP($E8, data_rekap_respon_1!$A:$E, 4, 0)="failed", IF(VLOOKUP($E8, data_rekap_respon_1!$A:$E, 5, 0)="Message Undeliverable.", "Invalid", "Failed"), "Received") ), "" )
A9: 1199 | D9: Hamba Allah | E9: 6282119025917 | G9: Masa Gajian | H9: PALESTINA | I9: May | J9: =_xlfn.IFNA(LEFT(VLOOKUP($E9,data_rekap_respon_1!$A:$E,3,0),10),"") | L9: =_xlfn.IFNA( IF(VLOOKUP($E9, data_rekap_respon_1!$A:$E, 4, 0)="read", "Read", IF(VLOOKUP($E9, data_rekap_respon_1!$A:$E, 4, 0)="failed", IF(VLOOKUP($E9, data_rekap_respon_1!$A:$E, 5, 0)="Message Undeliverable.", "Invalid", "Failed"), "Received") ), "" )
A10: 1422 | D10: Hamba Allah | E10: 6285693876515 | G10: Masa Gajian | H10: PALESTINA | I10: May | J10: =_xlfn.IFNA(LEFT(VLOOKUP($E10,data_rekap_respon_1!$A:$E,3,0),10),"") | L10: =_xlfn.IFNA( IF(VLOOKUP($E10, data_rekap_respon_1!$A:$E, 4, 0)="read", "Read", IF(VLOOKUP($E10, data_rekap_respon_1!$A:$E, 4, 0)="failed", IF(VLOOKUP($E10, data_rekap_respon_1!$A:$E, 5, 0)="Message Undeliverable.", "Invalid", "Failed"), "Received") ), "" )
A11: 1426 | D11: Hamba Allah | E11: 62818110674 | G11: Bukan Gajian | H11: PALESTINA | I11: May | J11: =_xlfn.IFNA(LEFT(VLOOKUP($E11,data_rekap_respon_1!$A:$E,3,0),10),"") | L11: =_xlfn.IFNA( IF(VLOOKUP($E11, data_rekap_respon_1!$A:$E, 4, 0)="read", "Read", IF(VLOOKUP($E11, data_rekap_respon_1!$A:$E, 4, 0)="failed", IF(VLOOKUP($E11, data_rekap_respon_1!$A:$E, 5, 0)="Message Undeliverable.", "Invalid", "Failed"), "Received") ), "" )
A12: 1520 | D12: Hamba Allah | E12: 628563027847 | G12: Masa Gajian | H12: PALESTINA | I12: May | J12: =_xlfn.IFNA(LEFT(VLOOKUP($E12,data_rekap_respon_1!$A:$E,3,0),10),"") | L12: =_xlfn.IFNA( IF(VLOOKUP($E12, data_rekap_respon_1!$A:$E, 4, 0)="read", "Read", IF(VLOOKUP($E12, data_rekap_respon_1!$A:$E, 4, 0)="failed", IF(VLOOKUP($E12, data_rekap_respon_1!$A:$E, 5, 0)="Message Undeliverable.", "Invalid", "Failed"), "Received") ), "" )
A13: 1578 | D13: Hamba Allah | E13: 6285652134978 | G13: Bukan Gajian | H13: PALESTINA | I13: May | J13: =_xlfn.IFNA(LEFT(VLOOKUP($E13,data_rekap_respon_1!$A:$E,3,0),10),"") | L13: =_xlfn.IFNA( IF(VLOOKUP($E13, data_rekap_respon_1!$A:$E, 4, 0)="read", "Read", IF(VLOOKUP($E13, data_rekap_respon_1!$A:$E, 4, 0)="failed", IF(VLOOKUP($E13, data_rekap_respon_1!$A:$E, 5, 0)="Message Undeliverable.", "Invalid", "Failed"), "Received") ), "" )
... A4011: 10820 | D4011: sunaryo | E4011: 6281553393373 | G4011: Masa Gajian | H4011: PALESTINA | I4011: June | J4011: =_xlfn.IFNA(LEFT(VLOOKUP($E4011,data_rekap_respon_1!$A:$E,3,0),10),"") | L4011: =_xlfn.IFNA( IF(VLOOKUP($E4011, data_rekap_respon_1!$A:$E, 4, 0)="read", "Read", IF(VLOOKUP($E4011, data_rekap_respon_1!$A:$E, 4, 0)="failed", IF(VLOOKUP($E4011, data_rekap_respon_1!$A:$E, 5, 0)="Message Undeliverable.", "Invalid", "Failed"), "Received") ), "" )
A4012: 10821 | E4012: 6281553504555 | G4012: Bukan Gajian | H4012: PALESTINA | I4012: June | J4012: =_xlfn.IFNA(LEFT(VLOOKUP($E4012,data_rekap_respon_1!$A:$E,3,0),10),"") | L4012: =_xlfn.IFNA( IF(VLOOKUP($E4012, data_rekap_respon_1!$A:$E, 4, 0)="read", "Read", IF(VLOOKUP($E4012, data_rekap_respon_1!$A:$E, 4, 0)="failed", IF(VLOOKUP($E4012, data_rekap_respon_1!$A:$E, 5, 0)="Message Undeliverable.", "Invalid", "Failed"), "Received") ), "" )
A4013: 10822 | D4013: Moch soleh | E4013: 6281553622229 | G4013: Bukan Gajian | H4013: PALESTINA | I4013: June | J4013: =_xlfn.IFNA(LEFT(VLOOKUP($E4013,data_rekap_respon_1!$A:$E,3,0),10),"") | L4013: =_xlfn.IFNA( IF(VLOOKUP($E4013, data_rekap_respon_1!$A:$E, 4, 0)="read", "Read", IF(VLOOKUP($E4013, data_rekap_respon_1!$A:$E, 4, 0)="failed", IF(VLOOKUP($E4013, data_rekap_respon_1!$A:$E, 5, 0)="Message Undeliverable.", "Invalid", "Failed"), "Received") ), "" )
A4014: 10823 | D4014: ANING collection | E4014: 6281553851943 | G4014: Masa Gajian | H4014: PALESTINA | I4014: June | J4014: =_xlfn.IFNA(LEFT(VLOOKUP($E4014,data_rekap_respon_1!$A:$E,3,0),10),"") | L4014: =_xlfn.IFNA( IF(VLOOKUP($E4014, data_rekap_respon_1!$A:$E, 4, 0)="read", "Read", IF(VLOOKUP($E4014, data_rekap_respon_1!$A:$E, 4, 0)="failed", IF(VLOOKUP($E4014, data_rekap_respon_1!$A:$E, 5, 0)="Message Undeliverable.", "Invalid", "Failed"), "Received") ), "" )
A4015: 10824 | D4015: Fulan | E4015: 6281554456880 | G4015: Masa Gajian | H4015: PALESTINA | I4015: June | J4015: =_xlfn.IFNA(LEFT(VLOOKUP($E4015,data_rekap_respon_1!$A:$E,3,0),10),"") | L4015: =_xlfn.IFNA( IF(VLOOKUP($E4015, data_rekap_respon_1!$A:$E, 4, 0)="read", "Read", IF(VLOOKUP($E4015, data_rekap_respon_1!$A:$E, 4, 0)="failed", IF(VLOOKUP($E4015, data_rekap_respon_1!$A:$E, 5, 0)="Message Undeliverable.", "Invalid", "Failed"), "Received") ), "" )
A4016: 10825 | D4016: Bambang | E4016: 6281555316325 | G4016: Bukan Gajian | H4016: PALESTINA | I4016: June | J4016: =_xlfn.IFNA(LEFT(VLOOKUP($E4016,data_rekap_respon_1!$A:$E,3,0),10),"") | L4016: =_xlfn.IFNA( IF(VLOOKUP($E4016, data_rekap_respon_1!$A:$E, 4, 0)="read", "Read", IF(VLOOKUP($E4016, data_rekap_respon_1!$A:$E, 4, 0)="failed", IF(VLOOKUP($E4016, data_rekap_respon_1!$A:$E, 5, 0)="Message Undeliverable.", "Invalid", "Failed"), "Received") ), "" )
A4017: 10826 | D4017: Abdul fatah | E4017: 628155555225222 | G4017: Masa Gajian | H4017: PALESTINA | I4017: June | J4017: =_xlfn.IFNA(LEFT(VLOOKUP($E4017,data_rekap_respon_1!$A:$E,3,0),10),"") | L4017: =_xlfn.IFNA( IF(VLOOKUP($E4017, data_rekap_respon_1!$A:$E, 4, 0)="read", "Read", IF(VLOOKUP($E4017, data_rekap_respon_1!$A:$E, 4, 0)="failed", IF(VLOOKUP($E4017, data_rekap_respon_1!$A:$E, 5, 0)="Message Undeliverable.", "Invalid", "Failed"), "Received") ), "" )
A4018: 10827 | D4018: Hamba Allah | E4018: 6281555586485 | G4018: Masa Gajian | H4018: PALESTINA | I4018: June | J4018: =_xlfn.IFNA(LEFT(VLOOKUP($E4018,data_rekap_respon_1!$A:$E,3,0),10),"") | L4018: =_xlfn.IFNA( IF(VLOOKUP($E4018, data_rekap_respon_1!$A:$E, 4, 0)="read", "Read", IF(VLOOKUP($E4018, data_rekap_respon_1!$A:$E, 4, 0)="failed", IF(VLOOKUP($E4018, data_rekap_respon_1!$A:$E, 5, 0)="Message Undeliverable.", "Invalid", "Failed"), "Received") ), "" )
A4019: 10828 | D4019: Fitri R | E4019: 6281548739878 | G4019: Bukan Gajian | H4019: PALESTINA | I4019: June | J4019: =_xlfn.IFNA(LEFT(VLOOKUP($E4019,data_rekap_respon_1!$A:$E,3,0),10),"") | L4019: =_xlfn.IFNA( IF(VLOOKUP($E4019, data_rekap_respon_1!$A:$E, 4, 0)="read", "Read", IF(VLOOKUP($E4019, data_rekap_respon_1!$A:$E, 4, 0)="failed", IF(VLOOKUP($E4019, data_rekap_respon_1!$A:$E, 5, 0)="Message Undeliverable.", "Invalid", "Failed"), "Received") ), "" )
A4020: 10829 | D4020: Jasiati Paputungan | E4020: 6285240331502 | G4020: Bukan Gajian | H4020: PALESTINA | I4020: June | J4020: =_xlfn.IFNA(LEFT(VLOOKUP($E4020,data_rekap_respon_1!$A:$E,3,0),10),"") | L4020: =_xlfn.IFNA( IF(VLOOKUP($E4020, data_rekap_respon_1!$A:$E, 4, 0)="read", "Read", IF(VLOOKUP($E4020, data_rekap_respon_1!$A:$E, 4, 0)="failed", IF(VLOOKUP($E4020, data_rekap_respon_1!$A:$E, 5, 0)="Message Undeliverable.", "Invalid", "Failed"), "Received") ), "" )
A4021: 10830 | D4021: Siti Rohaniah | E4021: 6281999805980 | G4021: Masa Gajian | H4021: PALESTINA | I4021: June | J4021: =_xlfn.IFNA(LEFT(VLOOKUP($E4021,data_rekap_respon_1!$A:$E,3,0),10),"") | L4021: =_xlfn.IFNA( IF(VLOOKUP($E4021, data_rekap_respon_1!$A:$E, 4, 0)="read", "Read", IF(VLOOKUP($E4021, data_rekap_respon_1!$A:$E, 4, 0)="failed", IF(VLOOKUP($E4021, data_rekap_respon_1!$A:$E, 5, 0)="Message Undeliverable.", "Invalid", "Failed"), "Received") ), "" )
A4022: 10831 | D4022: Oriza | E4022: 6282110007879 | G4022: Masa Gajian | H4022: PALESTINA | I4022: June | J4022: =_xlfn.IFNA(LEFT(VLOOKUP($E4022,data_rekap_respon_1!$A:$E,3,0),10),"") | L4022: =_xlfn.IFNA( IF(VLOOKUP($E4022, data_rekap_respon_1!$A:$E, 4, 0)="read", "Read", IF(VLOOKUP($E4022, data_rekap_respon_1!$A:$E, 4, 0)="failed", IF(VLOOKUP($E4022, data_rekap_respon_1!$A:$E, 5, 0)="Message Undeliverable.", "Invalid", "Failed"), "Received") ), "" )
A4023: 10832 | D4023: Hamba sahaya | E4023: 6282177755516 | G4023: Bukan Gajian | H4023: PALESTINA | I4023: June | J4023: =_xlfn.IFNA(LEFT(VLOOKUP($E4023,data_rekap_respon_1!$A:$E,3,0),10),"") | L4023: =_xlfn.IFNA( IF(VLOOKUP($E4023, data_rekap_respon_1!$A:$E, 4, 0)="read", "Read", IF(VLOOKUP($E4023, data_rekap_respon_1!$A:$E, 4, 0)="failed", IF(VLOOKUP($E4023, data_rekap_respon_1!$A:$E, 5, 0)="Message Undeliverable.", "Invalid", "Failed"), "Received") ), "" )
A4024: 10833 | D4024: Hamba Allah | E4024: 6282177847606 | G4024: Bukan Gajian | H4024: PALESTINA | I4024: June | J4024: =_xlfn.IFNA(LEFT(VLOOKUP($E4024,data_rekap_respon_1!$A:$E,3,0),10),"") | L4024: =_xlfn.IFNA( IF(VLOOKUP($E4024, data_rekap_respon_1!$A:$E, 4, 0)="read", "Read", IF(VLOOKUP($E4024, data_rekap_respon_1!$A:$E, 4, 0)="failed", IF(VLOOKUP($E4024, data_rekap_respon_1!$A:$E, 5, 0)="Message Undeliverable.", "Invalid", "Failed"), "Received") ), "" )
... A4607: 11416 | D4607: Nama | E4607: 62899999999 | G4607: Bukan Gajian | H4607: PALESTINA | I4607: June | J4607: =_xlfn.IFNA(LEFT(VLOOKUP($E4607,data_rekap_respon_1!$A:$E,3,0),10),"") | L4607: =_xlfn.IFNA( IF(VLOOKUP($E4607, data_rekap_respon_1!$A:$E, 4, 0)="read", "Read", IF(VLOOKUP($E4607, data_rekap_respon_1!$A:$E, 4, 0)="failed", IF(VLOOKUP($E4607, data_rekap_respon_1!$A:$E, 5, 0)="Message Undeliverable.", "Invalid", "Failed"), "Received") ), "" )

Sheet data_rekap_respon_1
A1: Phone Number | B1: Name | C1: Send At | D1: Status | E1: Error
A2: 6281315011294 | B2: Welda mudiar | C2: 2025-07-10T06:58:36.803Z | D2: delivered
A3: 628126304708 | B3: Wibowo | C3: 2025-07-10T06:58:36.803Z | D3: read
A4: 628123358126 | B4: Wildah | C4: 2025-07-10T06:58:36.803Z | D4: delivered
A5: 6281312503017 | B5: Wirawan | C5: 2025-07-10T06:58:36.803Z | D5: delivered
A6: 62811805204 | B6: Wita | C6: 2025-07-10T06:58:36.803Z | D6: delivered
A7: 6281289779086 | B7: Wita | C7: 2025-07-10T06:58:36.803Z | D7: delivered
A8: 628129325397 | B8: Wiwie Damayanti binti Soetarno | C8: 2025-07-10T06:58:36.803Z | D8: read
A9: 628123094260 | B9: Wiwik Pradiana | C9: 2025-07-10T06:58:36.803Z | D9: delivered
A10: 6281290016322 | B10: Wiwik Widiastutik | C10: 2025-07-10T06:58:36.803Z | D10: read
A11: 6285242481811 | B11: Wiwin Fitriani | C11: 2025-07-10T06:58:36.803Z | D11: read
A12: 6285697781876 | C12: 2025-07-10T06:58:36.803Z | D12: read
A13: 6281809123345 | B13: Wnn N | C13: 2025-07-10T06:58:36.803Z | D13: failed | E13: Message Undeliverable.
A14: 6281310111123 | B14: Wolter yunk | C14: 2025-07-10T06:58:36.803Z | D14: read
A15: 6281349113387 | B15: Wulandari | C15: 2025-07-10T06:58:36.803Z | D15: read
A16: 6281260777770 | B16: Yan hizrin | C16: 2025-07-10T06:58:36.803Z | D16: read
A17: 6283872943805 | B17: Yana Suryana | C17: 2025-07-10T06:58:36.803Z | D17: delivered
A18: 6281311989865 | B18: Yani Koesman | C18: 2025-07-10T06:58:36.803Z | D18: delivered
A19: 6281213960511 | B19: Yanti Nadya | C19: 2025-07-10T06:58:36.803Z | D19: delivered
A20: 6281318009653 | B20: Yati | C20: 2025-07-10T06:58:36.803Z | D20: delivered
A21: 6281324214680 | B21: Yayah Fajriah | C21: 2025-07-10T06:58:36.803Z | D21: read
A22: 6285209441444 | B22: Yayan | C22: 2025-07-10T06:58:36.803Z | D22: failed | E22: Message Undeliverable.
A23: 6281230805381 | B23: Ye | C23: 2025-07-10T06:58:36.803Z | D23: read
A24: 6281331310533 | B24: Yeki | C24: 2025-07-10T06:58:36.803Z | D24: delivered
A25: 6281575780546 | B25: Yohansyah | C25: 2025-07-10T06:58:36.803Z | D25: delivered
A26: 6281542772923 | B26: Yono | C26: 2025-07-10T06:58:36.803Z | D26: read
A27: 6281267111100 | B27: Yose | C27: 2025-07-10T06:58:36.803Z | D27: read
A28: 628128152371 | B28: Yossy Chandra | C28: 2025-07-10T06:58:36.803Z | D28: read
A29: 6285860154590 | B29: Yuauf adhirekso nurakhman | C29: 2025-07-10T06:58:36.803Z | D29: delivered
A30: 6281314081263 | B30: Yudhi Aribowo | C30: 2025-07-10T06:58:36.803Z | D30: read
A31: 6281347773330 | B31: Yudi Hanapiah | C31: 2025-07-10T06:58:36.803Z | D31: delivered
A32: 6281259186594 | B32: Yudi Rizal | C32: 2025-07-10T06:58:36.803Z | D32: delivered
A33: 628125294630 | B33: Yunaeni | C33: 2025-07-10T06:58:36.803Z | D33: failed | E33: Message Undeliverable.
A34: 628118823066 | B34: Yuni | C34: 2025-07-10T06:58:36.803Z | D34: read
A35: 6281319224988 | B35: Yuniar Olii | C35: 2025-07-10T06:58:36.803Z | D35: delivered
A36: 6281227009397 | B36: Yunita | C36: 2025-07-10T06:58:36.803Z | D36: read
A37: 6281319427794 | B37: Yusnel | C37: 2025-07-10T06:58:36.803Z | D37: read
A38: 628114112050 | B38: Yusran Nas | C38: 2025-07-10T06:58:36.803Z | D38: read
A39: 6281250999897 | B39: Yustiadi | C39: 2025-07-10T06:58:36.803Z | D39: delivered
A40: 6281335570000 | B40: Yuvit shafa | C40: 2025-07-10T06:58:36.803Z | D40: read
...

Sheet Lembar1
A1: Action | B1: Respon | C1: Prospek
A2: Inisiasi | B2: Invalid | C2: Penawaran Program
A3: Kirim Kwitansi | B3: Ceklis 1 | C3: Cross Selling
A4: Kirim Laporan | B4: Received | C4: Hard Selling
A5: Doakan donatur | B5: Read
A6: Kalimat Inspiratif | B6: Obrolan aktif
A7: Penawaran Program | B7: Obrolan Pasif
A8: Cross Selling | B8: Donasi
A9: Hard Selling | B9: Keluhan
A10: *Khusus di hari jumat untuk proses interaksi script disisipkan call to action di akhir | B10: lain lain
B11: Promise to donate
A13: Jika ada Donatur yang berdonasi tanpa di Blast MAKA Cek apakah Nomor Donatur tercatat di data himpunan pribadi CS
A14: Jika iya maka Ubah kolom Respon menjadi 'donasi' dan isi nominal di kolom donasi
A15: Jika tidak, maka silahkan buat baris baru dan isi kolom Action, Respon, Donasi
A17: HARAP ISI SESUAI FORMAT
