Workbook

Sheet Donatur
A1: Donatur | B1: Whatsapp | C1: Tanggal | D1: Status | E1: Error
A2: Suminah | B2: 6285753301575 | C2: =LEFT(VLOOKUP($B2,Hasil!$A:$E,3,FALSE),10) -> 2025-07-10 | D2: =VLOOKUP($B2,Hasil!$A:$E,4,FALSE) -> delivered | E2: =_xlfn.IFNA(VLOOKUP($B2,Hasil!$A:$E,5,FALSE)," ") -> 0
A3: M Rizqi Syahputra | B3: 62881082355438 | C3: =LEFT(VLOOKUP($B3,Hasil!$A:$E,3,FALSE),10) -> 2025-07-10 | D3: =VLOOKUP($B3,Hasil!A:E,4,FALSE) -> failed | E3: =_xlfn.IFNA(VLOOKUP($B3,Hasil!$A:$E,5,FALSE)," ") -> Failed to send message because this user's phone number is part of an experiment
A4: Noto | B4: 628226357000 | C4: =LEFT(VLOOKUP($B4,Hasil!$A:$E,3,FALSE),10) -> 2025-07-10 | D4: =VLOOKUP($B4,Hasil!A:E,4,FALSE) -> failed | E4: =_xlfn.IFNA(VLOOKUP($B4,Hasil!$A:$E,5,FALSE)," ") -> Message Undeliverable.
A5: Orang dari SMAIT Cahaya Bangsa | B5: 6282236899125 | C5: =LEFT(VLOOKUP($B5,Hasil!$A:$E,3,FALSE),10) -> 2025-07-10 | D5: =VLOOKUP($B5,Hasil!A:E,4,FALSE) -> read | E5: =_xlfn.IFNA(VLOOKUP($B5,Hasil!$A:$E,5,FALSE)," ") -> 0
A6: Hj Asnaina Aliuntu | B6: 6282380878760 | C6: =LEFT(VLOOKUP($B6,Hasil!$A:$E,3,FALSE),10) -> 2025-07-10 | D6: =VLOOKUP($B6,Hasil!A:E,4,FALSE) -> delivered | E6: =_xlfn.IFNA(VLOOKUP($B6,Hasil!$A:$E,5,FALSE)," ") -> 0
A7: Muhammad F | B7: 628561889392 | C7: =LEFT(VLOOKUP($B7,Hasil!$A:$E,3,FALSE),10) -> 2025-07-10 | D7: =VLOOKUP($B7,Hasil!A:E,4,FALSE) -> delivered | E7: =_xlfn.IFNA(VLOOKUP($B7,Hasil!$A:$E,5,FALSE)," ") -> 0
A8: Tins | B8: 6281266789959 | C8: =LEFT(VLOOKUP($B8,Hasil!$A:$E,3,FALSE),10) -> 2025-07-10 | D8: =VLOOKUP($B8,Hasil!A:E,4,FALSE) -> read | E8: =_xlfn.IFNA(VLOOKUP($B8,Hasil!$A:$E,5,FALSE)," ") -> 0
A9: Yose | B9: 6281267111100 | C9: =LEFT(VLOOKUP($B9,Hasil!$A:$E,3,FALSE),10) -> 2025-07-10 | D9: =VLOOKUP($B9,Hasil!A:E,4,FALSE) -> read | E9: =_xlfn.IFNA(VLOOKUP($B9,Hasil!$A:$E,5,FALSE)," ") -> 0
A10: Rinda Lestari | B10: 6283190009388 | C10: =LEFT(VLOOKUP($B10,Hasil!$A:$E,3,FALSE),10) -> 2025-07-10 | D10: =VLOOKUP($B10,Hasil!A:E,4,FALSE) -> failed | E10: =_xlfn.IFNA(VLOOKUP($B10,Hasil!$A:$E,5,FALSE)," ") -> Message Undeliverable.
A11: Suldistiano | B11: 6283188034477 | C11: =LEFT(VLOOKUP($B11,Hasil!$A:$E,3,FALSE),10) -> 2025-07-10 | D11: =VLOOKUP($B11,Hasil!A:E,4,FALSE) -> delivered | E11: =_xlfn.IFNA(VLOOKUP($B11,Hasil!$A:$E,5,FALSE)," ") -> 0
A12: Hamba ALLOH | B12: 6281267130353 | C12: =LEFT(VLOOKUP($B12,Hasil!$A:$E,3,FALSE),10) -> 2025-07-10 | D12: =VLOOKUP($B12,Hasil!A:E,4,FALSE) -> read | E12: =_xlfn.IFNA(VLOOKUP($B12,Hasil!$A:$E,5,FALSE)," ") -> 0
A13: Euis Sopiah | B13: 6281221425526 | C13: =LEFT(VLOOKUP($B13,Hasil!$A:$E,3,FALSE),10) -> 2025-07-10 | D13: =VLOOKUP($B13,Hasil!A:E,4,FALSE) -> delivered | E13: =_xlfn.IFNA(VLOOKUP($B13,Hasil!$A:$E,5,FALSE)," ") -> 0
A14: Adit | B14: 6282131999733 | C14: =LEFT(VLOOKUP($B14,Hasil!$A:$E,3,FALSE),10) -> 2025-07-10 | D14: =VLOOKUP($B14,Hasil!A:E,4,FALSE) -> read | E14: =_xlfn.IFNA(VLOOKUP($B14,Hasil!$A:$E,5,FALSE)," ") -> 0
... A5109: Hamba allah | B5109: 6285248526045 | C5109: =LEFT(VLOOKUP($B5109,Hasil!$A:$E,3,FALSE),10) -> #N/A | D5109: =VLOOKUP($B5109,Hasil!A:E,4,FALSE) -> #N/A | E5109: =_xlfn.IFNA(VLOOKUP($B5109,Hasil!$A:$E,5,FALSE)," ")
B5110: 6285248447499 | C5110: =LEFT(VLOOKUP($B5110,Hasil!$A:$E,3,FALSE),10) -> #N/A | D5110: =VLOOKUP($B5110,Hasil!A:E,4,FALSE) -> #N/A | E5110: =_xlfn.IFNA(VLOOKUP($B5110,Hasil!$A:$E,5,FALSE)," ")
A5111: Paridah | B5111: 6285249516041 | C5111: =LEFT(VLOOKUP($B5111,Hasil!$A:$E,3,FALSE),10) -> #N/A | D5111: =VLOOKUP($B5111,Hasil!A:E,4,FALSE) -> #N/A | E5111: =_xlfn.IFNA(VLOOKUP($B5111,Hasil!$A:$E,5,FALSE)," ")
A5112: Nn | B5112: 6289526895647 | C5112: =LEFT(VLOOKUP($B5112,Hasil!$A:$E,3,FALSE),10) -> #N/A | D5112: =VLOOKUP($B5112,Hasil!A:E,4,FALSE) -> #N/A | E5112: =_xlfn.IFNA(VLOOKUP($B5112,Hasil!$A:$E,5,FALSE)," ")
A5113: Sabiha Sari (E-Book) | B5113: 6289516181171 | C5113: =LEFT(VLOOKUP($B5113,Hasil!$A:$E,3,FALSE),10) -> #N/A | D5113: =VLOOKUP($B5113,Hasil!A:E,4,FALSE) -> #N/A | E5113: =_xlfn.IFNA(VLOOKUP($B5113,Hasil!$A:$E,5,FALSE)," ")
A5114: Hamba allah | B5114: 6289515485581 | C5114: =LEFT(VLOOKUP($B5114,Hasil!$A:$E,3,FALSE),10) -> #N/A | D5114: =VLOOKUP($B5114,Hasil!A:E,4,FALSE) -> #N/A | E5114: =_xlfn.IFNA(VLOOKUP($B5114,Hasil!$A:$E,5,FALSE)," ")
A5115: Rn | B5115: 6285263153786 | C5115: =LEFT(VLOOKUP($B5115,Hasil!$A:$E,3,FALSE),10) -> #N/A | D5115: =VLOOKUP($B5115,Hasil!A:E,4,FALSE) -> #N/A | E5115: =_xlfn.IFNA(VLOOKUP($B5115,Hasil!$A:$E,5,FALSE)," ")
A5116: Reni | B5116: 6289637497328 | C5116: =LEFT(VLOOKUP($B5116,Hasil!$A:$E,3,FALSE),10) -> #N/A | D5116: =VLOOKUP($B5116,Hasil!A:E,4,FALSE) -> #N/A | E5116: =_xlfn.IFNA(VLOOKUP($B5116,Hasil!$A:$E,5,FALSE)," ")
A5117: Uri pane | B5117: 62852612547797 | C5117: =LEFT(VLOOKUP($B5117,Hasil!$A:$E,3,FALSE),10) -> #N/A | D5117: =VLOOKUP($B5117,Hasil!A:E,4,FALSE) -> #N/A | E5117: =_xlfn.IFNA(VLOOKUP($B5117,Hasil!$A:$E,5,FALSE)," ")
A5118: Tresno Tresno | B5118: 6285261206272 | C5118: =LEFT(VLOOKUP($B5118,Hasil!$A:$E,3,FALSE),10) -> #N/A | D5118: =VLOOKUP($B5118,Hasil!A:E,4,FALSE) -> #N/A | E5118: =_xlfn.IFNA(VLOOKUP($B5118,Hasil!$A:$E,5,FALSE)," ")
A5119: nia kurniasih | B5119: 6289659184769 | C5119: =LEFT(VLOOKUP($B5119,Hasil!$A:$E,3,FALSE),10) -> #N/A | D5119: =VLOOKUP($B5119,Hasil!A:E,4,FALSE) -> #N/A | E5119: =_xlfn.IFNA(VLOOKUP($B5119,Hasil!$A:$E,5,FALSE)," ")
A5120: bismillahirrahmanirrahim | B5120: 6289527945985 | C5120: =LEFT(VLOOKUP($B5120,Hasil!$A:$E,3,FALSE),10) -> #N/A | D5120: =VLOOKUP($B5120,Hasil!A:E,4,FALSE) -> #N/A | E5120: =_xlfn.IFNA(VLOOKUP($B5120,Hasil!$A:$E,5,FALSE)," ")
A5121: Brantasdi | B5121: 6289636325512 | C5121: =LEFT(VLOOKUP($B5121,Hasil!$A:$E,3,FALSE),10) -> #N/A | D5121: =VLOOKUP($B5121,Hasil!A:E,4,FALSE) -> #N/A | E5121: =_xlfn.IFNA(VLOOKUP($B5121,Hasil!$A:$E,5,FALSE)," ")
A5122: Maila | B5122: 6285248098068 | C5122: =LEFT(VLOOKUP($B5122,Hasil!$A:$E,3,FALSE),10) -> #N/A | D5122: =VLOOKUP($B5122,Hasil!A:E,4,FALSE) -> #N/A | E5122: =_xlfn.IFNA(VLOOKUP($B5122,Hasil!$A:$E,5,FALSE)," ")
... A6267: Darmi | B6267: 6285274336593 | C6267: =LEFT(VLOOKUP($B6267,Hasil!$A:$E,3,FALSE),10) -> #N/A | D6267: =VLOOKUP($B6267,Hasil!A:E,4,FALSE) -> #N/A | E6267: =_xlfn.IFNA(VLOOKUP($B6267,Hasil!$A:$E,5,FALSE)," ")
B6268: 6287886526415 | C6268: =LEFT(VLOOKUP($B6268,Hasil!$A:$E,3,FALSE),10) -> #N/A | D6268: =VLOOKUP($B6268,Hasil!A:E,4,FALSE) -> #N/A | E6268: =_xlfn.IFNA(VLOOKUP($B6268,Hasil!$A:$E,5,FALSE)," ")
A6269: Meri | B6269: 6285274327254 | C6269: =LEFT(VLOOKUP($B6269,Hasil!$A:$E,3,FALSE),10) -> #N/A | D6269: =VLOOKUP($B6269,Hasil!A:E,4,FALSE) -> #N/A | E6269: =_xlfn.IFNA(VLOOKUP($B6269,Hasil!$A:$E,5,FALSE)," ")
A6270: Shalihatul Putri | B6270: 6285274296768 | C6270: =LEFT(VLOOKUP($B6270,Hasil!$A:$E,3,FALSE),10) -> #N/A | D6270: =VLOOKUP($B6270,Hasil!A:E,4,FALSE) -> #N/A | E6270: =_xlfn.IFNA(VLOOKUP($B6270,Hasil!$A:$E,5,FALSE)," ")
A6271: Nurul hidayati | B6271: 6287886631630 | C6271: =LEFT(VLOOKUP($B6271,Hasil!$A:$E,3,FALSE),10) -> #N/A | D6271: =VLOOKUP($B6271,Hasil!A:E,4,FALSE) -> #N/A | E6271: =_xlfn.IFNA(VLOOKUP($B6271,Hasil!$A:$E,5,FALSE)," ")
A6272: Yulia marta | B6272: 6285274244987 | C6272: =LEFT(VLOOKUP($B6272,Hasil!$A:$E,3,FALSE),10) -> #N/A | D6272: =VLOOKUP($B6272,Hasil!A:E,4,FALSE) -> #N/A | E6272: =_xlfn.IFNA(VLOOKUP($B6272,Hasil!$A:$E,5,FALSE)," ")
A6273: Hamba Allah | B6273: 6287886735745 | C6273: =LEFT(VLOOKUP($B6273,Hasil!$A:$E,3,FALSE),10) -> #N/A | D6273: =VLOOKUP($B6273,Hasil!A:E,4,FALSE) -> #N/A | E6273: =_xlfn.IFNA(VLOOKUP($B6273,Hasil!$A:$E,5,FALSE)," ")
A6274: Hendra | B6274: 6285274243384 | C6274: =LEFT(VLOOKUP($B6274,Hasil!$A:$E,3,FALSE),10) -> #N/A | D6274: =VLOOKUP($B6274,Hasil!A:E,4,FALSE) -> #N/A | E6274: =_xlfn.IFNA(VLOOKUP($B6274,Hasil!$A:$E,5,FALSE)," ")
A6275: Silvia | B6275: 6285274201203 | C6275: =LEFT(VLOOKUP($B6275,Hasil!$A:$E,3,FALSE),10) -> #N/A | D6275: =VLOOKUP($B6275,Hasil!A:E,4,FALSE) -> #N/A | E6275: =_xlfn.IFNA(VLOOKUP($B6275,Hasil!$A:$E,5,FALSE)," ")
A6276: Yoga | B6276: 6287886517172 | C6276: =LEFT(VLOOKUP($B6276,Hasil!$A:$E,3,FALSE),10) -> #N/A | D6276: =VLOOKUP($B6276,Hasil!A:E,4,FALSE) -> #N/A | E6276: =_xlfn.IFNA(VLOOKUP($B6276,Hasil!$A:$E,5,FALSE)," ")
A6277: HM. Rojaya | B6277: 6287877378966 | C6277: =LEFT(VLOOKUP($B6277,Hasil!$A:$E,3,FALSE),10) -> #N/A | D6277: =VLOOKUP($B6277,Hasil!A:E,4,FALSE) -> #N/A | E6277: =_xlfn.IFNA(VLOOKUP($B6277,Hasil!$A:$E,5,FALSE)," ")
A6278: H andri | B6278: 6287885120484 | C6278: =LEFT(VLOOKUP($B6278,Hasil!$A:$E,3,FALSE),10) -> #N/A | D6278: =VLOOKUP($B6278,Hasil!A:E,4,FALSE) -> #N/A | E6278: =_xlfn.IFNA(VLOOKUP($B6278,Hasil!$A:$E,5,FALSE)," ")
...

Sheet Hasil
A1: Phone Number | B1: Name | C1: Send At | D1: Status | E1: Error
A2: 6281315011294 | B2: Welda mudiar | C2: 2025-07-10T06:58:36.803Z | D2: delivered
A3: 628126304708 | B3: Wibowo | C3: 2025-07-10T06:58:36.803Z | D3: read
A4: 628123358126 | B4: Wildah | C4: 2025-07-10T06:58:36.803Z | D4: delivered
A5: 6281312503017 | B5: Wirawan | C5: 2025-07-10T06:58:36.803Z | D5: delivered
A6: 62811805204 | B6: Wita | C6: 2025-07-10T06:58:36.803Z | D6: delivered
A7: 6281289779086 | B7: Wita | C7: 2025-07-10T06:58:36.803Z | D7: delivered
A8: 628129325397 | B8: Wiwie Damayanti binti Soetarno | C8: 2025-07-10T06:58:36.803Z | D8: read
A9: 628123094260 | B9: Wiwik Pradiana | C9: 2025-07-10T06:58:36.803Z | D9: delivered
A10: 6281290016322 | B10: Wiwik Widiastutik | C10: 2025-07-10T06:58:36.803Z | D10: read
A11: 6285242481811 | B11: Wiwin Fitriani | C11: 2025-07-10T06:58:36.803Z | D11: read
A12: 6285697781876 | B12: Wk | C12: 2025-07-10T06:58:36.803Z | D12: read
A13: 6281809123345 | B13: Wnn N | C13: 2025-07-10T06:58:36.803Z | D13: failed | E13: Message Undeliverable.
A14: 6281310111123 | B14: Wolter yunk | C14: 2025-07-10T06:58:36.803Z | D14: read
A15: 6281349113387 | B15: Wulandari | C15: 2025-07-10T06:58:36.803Z | D15: read
A16: 6281260777770 | B16: Yan hizrin | C16: 2025-07-10T06:58:36.803Z | D16: read
A17: 6283872943805 | B17: Yana Suryana | C17: 2025-07-10T06:58:36.803Z | D17: delivered
A18: 6281311989865 | B18: Yani Koesman | C18: 2025-07-10T06:58:36.803Z | D18: delivered
A19: 6281213960511 | B19: Yanti Nadya | C19: 2025-07-10T06:58:36.803Z | D19: delivered
A20: 6281318009653 | B20: Yati | C20: 2025-07-10T06:58:36.803Z | D20: delivered
A21: 6281324214680 | B21: Yayah Fajriah | C21: 2025-07-10T06:58:36.803Z | D21: read
A22: 6285209441444 | B22: Yayan | C22: 2025-07-10T06:58:36.803Z | D22: failed | E22: Message Undeliverable.
A23: 6281230805381 | B23: Ye | C23: 2025-07-10T06:58:36.803Z | D23: read
A24: 6281331310533 | B24: Yeki | C24: 2025-07-10T06:58:36.803Z | D24: delivered
A25: 6281575780546 | B25: Yohansyah | C25: 2025-07-10T06:58:36.803Z | D25: delivered
A26: 6281542772923 | B26: Yono | C26: 2025-07-10T06:58:36.803Z | D26: read
A27: 6281267111100 | B27: Yose | C27: 2025-07-10T06:58:36.803Z | D27: read
A28: 628128152371 | B28: Yossy Chandra | C28: 2025-07-10T06:58:36.803Z | D28: read
A29: 6285860154590 | B29: Yuauf adhirekso nurakhman | C29: 2025-07-10T06:58:36.803Z | D29: delivered
A30: 6281314081263 | B30: Yudhi Aribowo | C30: 2025-07-10T06:58:36.803Z | D30: read
A31: 6281347773330 | B31: Yudi Hanapiah | C31: 2025-07-10T06:58:36.803Z | D31: delivered
A32: 6281259186594 | B32: Yudi Rizal | C32: 2025-07-10T06:58:36.803Z | D32: delivered
A33: 628125294630 | B33: Yunaeni | C33: 2025-07-10T06:58:36.803Z | D33: failed | E33: Message Undeliverable.
A34: 628118823066 | B34: Yuni | C34: 2025-07-10T06:58:36.803Z | D34: read
A35: 6281319224988 | B35: Yuniar Olii | C35: 2025-07-10T06:58:36.803Z | D35: delivered
A36: 6281227009397 | B36: Yunita | C36: 2025-07-10T06:58:36.803Z | D36: read
A37: 6281319427794 | B37: Yusnel | C37: 2025-07-10T06:58:36.803Z | D37: read
A38: 628114112050 | B38: Yusran Nas | C38: 2025-07-10T06:58:36.803Z | D38: read
A39: 6281250999897 | B39: Yustiadi | C39: 2025-07-10T06:58:36.803Z | D39: delivered
A40: 6281335570000 | B40: Yuvit shafa | C40: 2025-07-10T06:58:36.803Z | D40: read
...
